<?xml version='1.0' encoding='utf-8'?>
<mujoco model="rby1">
  <compiler angle="radian" autolimits="true" eulerseq="xyz" />

  <default>
    <joint armature="10" damping="50" range="-3.14 3.14" />
    <material specular="0.5" shininess="0.25" />
  </default>

  <visual>
      <map force="0.1" zfar="30" />
      <rgba haze="0.15 0.25 0.35 1" />
      <quality shadowsize="4096" />
      <global offwidth="800" offheight="800" />
  </visual>

  <asset>
    <material name="0,0,0" specular="1.0" shininess="1.0" rgba="0.000000 0.000000 0.000000 1.000000" />
  <material name="10,10,10_LINK_6" specular="1.0" shininess="0.2" rgba="0.039216 0.039216 0.039216 1.000000" />
  <material name="10,10,10" specular="0.039216" shininess="1.0" rgba="0.039216 0.039216 0.039216 1.000000" />
  <material name="163,163,175" specular="1.0" shininess="0.2" rgba="0.639216 0.639216 0.686275 1.000000" />
  <material name="178,0,0" specular="1.0" shininess="0.2" rgba="0.698039 0.000000 0.000000 1.000000" />
  <material name="190,188,186" specular="1.0" shininess="0.2" rgba="0.745098 0.737255 0.729412 1.000000" />
  <material name="191,191,191" specular="0.0" shininess="0.3" rgba="0.749020 0.749020 0.749020 1.000000" />
  <material name="192,192,192" specular="1.0" shininess="0.2" rgba="0.752941 0.752941 0.752941 1.000000" />
  <material name="216,214,214" specular="1.0" shininess="0.2" rgba="0.847059 0.839216 0.839216 1.000000" />
  <material name="237,255,168" specular="1.0" shininess="0.2" rgba="0.929412 1.000000 0.658824 1.000000" />
  <material name="242,236,238" specular="1.0" shininess="0.2" rgba="0.949020 0.925490 0.933333 1.000000" />
  <material name="244,244,244" specular="0.9568629999999999" shininess="1.0" rgba="0.956863 0.956863 0.956863 1.000000" />
  <material name="25,25,25" specular="1.0" shininess="0.8" rgba="0.100000 0.100000 0.100000 1.000000" />
  <material name="254,254,255_LINK_6" specular="1.0" shininess="0.2" rgba="0.996078 0.996078 1.000000 1.000000" />
  <material name="254,254,255" specular="0.9973853333333333" shininess="1.0" rgba="0.996078 0.996078 1.000000 1.000000" />
  <material name="65,55,50" specular="1.0" shininess="0.2" rgba="0.254902 0.215686 0.196078 1.000000" />
  <material name="65,65,65" specular="0.254902" shininess="1.0" rgba="0.254902 0.254902 0.254902 1.000000" />
  <material name="69,69,69_1" specular="0.0" shininess="1.0" rgba="0.270588 0.270588 0.270588 1.000000" />
  <material name="69,69,69" specular="1.0" shininess="1.0" rgba="0.270588 0.270588 0.270588 1.000000" />
  <material name="70,70,70_FINGER" specular="0.27451" shininess="1.0" rgba="0.274510 0.274510 0.274510 1.000000" />
  <material name="70,70,70" specular="1.0" shininess="0.2" rgba="0.274510 0.274510 0.274510 1.000000" />
  <material name="79,79,79" specular="1.0" shininess="0.2" rgba="0.309804 0.309804 0.309804 1.000000" />
  <material name="80,80,80" specular="0.0" shininess="0.5" rgba="0.313725 0.313725 0.313725 1.000000" />
  <material name="156,168,171" specular="1.0" shininess="0.2" rgba="0.611765 0.658824 0.670588 1.000000" />
  <material name="130,130,130" specular="0.0" shininess="0.2" rgba="0.509804 0.509804 0.509804 1.000000" />
  <material name="90,90,90" specular="0.352941" shininess="1.0" rgba="0.352941 0.352941 0.352941 1.000000" />
  <material name="255,255,255" specular="1.0" shininess="0.2" rgba="1.000000 1.000000 1.000000 1.000000" />
<mesh file="base_0.obj" />
    <mesh file="base_1.obj" />
    <mesh file="base_2.obj" />
    <mesh file="base_3.obj" />
    <mesh file="base_4.obj" />
    <mesh file="base_5.obj" />
    <mesh file="base_6.obj" />
    <mesh file="base_7.obj" />  
<mesh file="MECANUM_WHEEL.obj" />
    <mesh file="MECANUM_WHEEL_collision_0.obj" />
    <mesh file="MECANUM_WHEEL_collision_1.obj" />
    <mesh file="MECANUM_WHEEL_collision_2.obj" />
    <mesh file="MECANUM_WHEEL_collision_3.obj" />
    <mesh file="MECANUM_WHEEL_collision_4.obj" />
    <mesh file="MECANUM_WHEEL_collision_5.obj" />
    <mesh file="MECANUM_WHEEL_collision_6.obj" />
    <mesh file="MECANUM_WHEEL_collision_7.obj" />
    <mesh file="MECANUM_WHEEL_collision_8.obj" />
    <mesh file="MECANUM_WHEEL_collision_9.obj" />
    <mesh file="MECANUM_WHEEL_collision_10.obj" />
    <mesh file="MECANUM_WHEEL_collision_11.obj" />
    <mesh file="MECANUM_WHEEL_collision_12.obj" />
    <mesh file="MECANUM_WHEEL_collision_13.obj" />
    <mesh file="MECANUM_WHEEL_collision_14.obj" />
    <mesh file="MECANUM_WHEEL_collision_15.obj" />
    <mesh file="MECANUM_WHEEL_collision_16.obj" />
    <mesh file="MECANUM_WHEEL_collision_17.obj" />
    <mesh file="MECANUM_WHEEL_collision_18.obj" />
    <mesh file="MECANUM_WHEEL_collision_19.obj" />
    <mesh file="MECANUM_WHEEL_collision_20.obj" />
    <mesh file="MECANUM_WHEEL_collision_21.obj" />
    <mesh file="MECANUM_WHEEL_collision_22.obj" />
    <mesh file="MECANUM_WHEEL_collision_23.obj" />
    <mesh file="MECANUM_WHEEL_collision_24.obj" />
    <mesh file="MECANUM_WHEEL_collision_25.obj" />
    <mesh file="MECANUM_WHEEL_collision_26.obj" />
    <mesh file="MECANUM_WHEEL_collision_27.obj" />
    <mesh file="MECANUM_WHEEL_collision_28.obj" />
    <mesh file="MECANUM_WHEEL_collision_29.obj" />
    <mesh file="MECANUM_WHEEL_collision_30.obj" />
    <mesh file="MECANUM_WHEEL_collision_31.obj" />
    <mesh file="MECANUM_WHEEL_collision_32.obj" />
    <mesh file="MECANUM_WHEEL_collision_33.obj" />
    <mesh file="MECANUM_WHEEL_collision_34.obj" />
    <mesh file="MECANUM_WHEEL_collision_35.obj" />
    <mesh file="MECANUM_WHEEL_collision_36.obj" />
    <mesh file="MECANUM_WHEEL_collision_37.obj" />
    <mesh file="MECANUM_WHEEL_collision_38.obj" />
    <mesh file="MECANUM_WHEEL_collision_39.obj" />
    <mesh file="MECANUM_WHEEL_collision_40.obj" />
    <mesh file="MECANUM_WHEEL_collision_41.obj" />
    <mesh file="MECANUM_WHEEL_collision_42.obj" />
    <mesh file="MECANUM_WHEEL_collision_43.obj" />
    <mesh file="MECANUM_WHEEL_collision_44.obj" />
    <mesh file="MECANUM_WHEEL_collision_45.obj" />
    <mesh file="MECANUM_WHEEL_collision_46.obj" />
    <mesh file="MECANUM_WHEEL_collision_47.obj" />
    <mesh file="MECANUM_WHEEL_collision_48.obj" />
    <mesh file="MECANUM_WHEEL_collision_49.obj" />
    <mesh file="MECANUM_WHEEL_collision_50.obj" />
    <mesh file="MECANUM_WHEEL_collision_51.obj" />
    <mesh file="MECANUM_WHEEL_collision_52.obj" />
    <mesh file="MECANUM_WHEEL_collision_53.obj" />
    <mesh file="MECANUM_WHEEL_collision_54.obj" />
    <mesh file="MECANUM_WHEEL_collision_55.obj" />
    <mesh file="MECANUM_WHEEL_collision_56.obj" />
    <mesh file="MECANUM_WHEEL_collision_57.obj" />
    <mesh file="MECANUM_WHEEL_collision_58.obj" />
    <mesh file="MECANUM_WHEEL_collision_59.obj" />
    <mesh file="MECANUM_WHEEL_collision_60.obj" />
    <mesh file="MECANUM_WHEEL_collision_61.obj" />
    <mesh file="MECANUM_WHEEL_collision_62.obj" />
    <mesh file="MECANUM_WHEEL_collision_63.obj" />
    <mesh file="MECANUM_WHEEL_collision_64.obj" />
    <mesh file="MECANUM_WHEEL_collision_65.obj" />
    <mesh file="MECANUM_WHEEL_collision_66.obj" />
    <mesh file="MECANUM_WHEEL_collision_67.obj" />
    <mesh file="MECANUM_WHEEL_collision_68.obj" />
    <mesh file="MECANUM_WHEEL_collision_69.obj" />
    <mesh file="MECANUM_WHEEL_collision_70.obj" />
<mesh file="MECANUM_WHEEL_M.obj" />
    <mesh file="MECANUM_WHEEL_M_collision_0.obj" />
    <mesh file="MECANUM_WHEEL_M_collision_1.obj" />
    <mesh file="MECANUM_WHEEL_M_collision_2.obj" />
    <mesh file="MECANUM_WHEEL_M_collision_3.obj" />
    <mesh file="MECANUM_WHEEL_M_collision_4.obj" />
    <mesh file="MECANUM_WHEEL_M_collision_5.obj" />
    <mesh file="MECANUM_WHEEL_M_collision_6.obj" />
    <mesh file="MECANUM_WHEEL_M_collision_7.obj" />
    <mesh file="MECANUM_WHEEL_M_collision_8.obj" />
    <mesh file="MECANUM_WHEEL_M_collision_9.obj" />
    <mesh file="MECANUM_WHEEL_M_collision_10.obj" />
    <mesh file="MECANUM_WHEEL_M_collision_11.obj" />
    <mesh file="MECANUM_WHEEL_M_collision_12.obj" />
    <mesh file="MECANUM_WHEEL_M_collision_13.obj" />
    <mesh file="MECANUM_WHEEL_M_collision_14.obj" />
    <mesh file="MECANUM_WHEEL_M_collision_15.obj" />
    <mesh file="MECANUM_WHEEL_M_collision_16.obj" />
    <mesh file="MECANUM_WHEEL_M_collision_17.obj" />
    <mesh file="MECANUM_WHEEL_M_collision_18.obj" />
    <mesh file="MECANUM_WHEEL_M_collision_19.obj" />
    <mesh file="MECANUM_WHEEL_M_collision_20.obj" />
    <mesh file="MECANUM_WHEEL_M_collision_21.obj" />
    <mesh file="MECANUM_WHEEL_M_collision_22.obj" />
    <mesh file="MECANUM_WHEEL_M_collision_23.obj" />
    <mesh file="MECANUM_WHEEL_M_collision_24.obj" />
    <mesh file="MECANUM_WHEEL_M_collision_25.obj" />
    <mesh file="MECANUM_WHEEL_M_collision_26.obj" />
    <mesh file="MECANUM_WHEEL_M_collision_27.obj" />
    <mesh file="MECANUM_WHEEL_M_collision_28.obj" />
    <mesh file="MECANUM_WHEEL_M_collision_29.obj" />
    <mesh file="MECANUM_WHEEL_M_collision_30.obj" />
    <mesh file="MECANUM_WHEEL_M_collision_31.obj" />
    <mesh file="MECANUM_WHEEL_M_collision_32.obj" />
    <mesh file="MECANUM_WHEEL_M_collision_33.obj" />
    <mesh file="MECANUM_WHEEL_M_collision_34.obj" />
    <mesh file="MECANUM_WHEEL_M_collision_35.obj" />
    <mesh file="MECANUM_WHEEL_M_collision_36.obj" />
    <mesh file="MECANUM_WHEEL_M_collision_37.obj" />
    <mesh file="MECANUM_WHEEL_M_collision_38.obj" />
    <mesh file="MECANUM_WHEEL_M_collision_39.obj" />
    <mesh file="MECANUM_WHEEL_M_collision_40.obj" />
    <mesh file="MECANUM_WHEEL_M_collision_41.obj" />
    <mesh file="MECANUM_WHEEL_M_collision_42.obj" />
    <mesh file="MECANUM_WHEEL_M_collision_43.obj" />
    <mesh file="MECANUM_WHEEL_M_collision_44.obj" />
    <mesh file="MECANUM_WHEEL_M_collision_45.obj" />
    <mesh file="MECANUM_WHEEL_M_collision_46.obj" />
    <mesh file="MECANUM_WHEEL_M_collision_47.obj" />
    <mesh file="MECANUM_WHEEL_M_collision_48.obj" />
    <mesh file="MECANUM_WHEEL_M_collision_49.obj" />
    <mesh file="MECANUM_WHEEL_M_collision_50.obj" />
    <mesh file="MECANUM_WHEEL_M_collision_51.obj" />
    <mesh file="MECANUM_WHEEL_M_collision_52.obj" />
    <mesh file="MECANUM_WHEEL_M_collision_53.obj" />
    <mesh file="MECANUM_WHEEL_M_collision_54.obj" />
    <mesh file="MECANUM_WHEEL_M_collision_55.obj" />
    <mesh file="MECANUM_WHEEL_M_collision_56.obj" />
    <mesh file="MECANUM_WHEEL_M_collision_57.obj" />
    <mesh file="MECANUM_WHEEL_M_collision_58.obj" />
    <mesh file="MECANUM_WHEEL_M_collision_59.obj" />
    <mesh file="MECANUM_WHEEL_M_collision_60.obj" />
    <mesh file="MECANUM_WHEEL_M_collision_61.obj" />
    <mesh file="MECANUM_WHEEL_M_collision_62.obj" />
    <mesh file="MECANUM_WHEEL_M_collision_63.obj" />
    <mesh file="MECANUM_WHEEL_M_collision_64.obj" />
    <mesh file="MECANUM_WHEEL_M_collision_65.obj" />
    <mesh file="MECANUM_WHEEL_M_collision_66.obj" />
    <mesh file="MECANUM_WHEEL_M_collision_67.obj" />
    <mesh file="MECANUM_WHEEL_M_collision_68.obj" />
    <mesh file="MECANUM_WHEEL_M_collision_69.obj" />
    <mesh file="MECANUM_WHEEL_M_collision_70.obj" />
    <mesh file="MECANUM_WHEEL_M_collision_71.obj" />
    <mesh file="MECANUM_WHEEL_M_collision_72.obj" />
    <mesh file="MECANUM_WHEEL_M_collision_73.obj" />
    <mesh file="MECANUM_WHEEL_M_collision_74.obj" />
    <mesh file="MECANUM_WHEEL_M_collision_75.obj" />
    <mesh file="MECANUM_WHEEL_M_collision_76.obj" />
    <mesh file="MECANUM_WHEEL_M_collision_77.obj" />
    <mesh file="MECANUM_WHEEL_M_collision_78.obj" />
    <mesh file="MECANUM_WHEEL_M_collision_79.obj" />
    <mesh file="MECANUM_WHEEL_M_collision_80.obj" />
    <mesh file="MECANUM_WHEEL_M_collision_81.obj" />
    <mesh file="MECANUM_WHEEL_M_collision_82.obj" />
    <mesh file="MECANUM_WHEEL_M_collision_83.obj" />
    <mesh file="MECANUM_WHEEL_M_collision_84.obj" />
<material name="235,235,235" specular="1.0" shininess="0.2" rgba="0.921569 0.921569 0.921569 1.000000" />
  <mesh file="WHEEL.obj" />
  <mesh file="WHEEL_collision_0.obj" />
  <mesh file="WHEEL_collision_1.obj" />
  <mesh file="WHEEL_collision_2.obj" />
  <mesh file="WHEEL_collision_3.obj" />
  <mesh file="WHEEL_collision_4.obj" />
  <mesh file="WHEEL_collision_5.obj" />
  <mesh file="WHEEL_collision_6.obj" />
  <mesh file="WHEEL_collision_7.obj" />
  <mesh file="WHEEL_collision_8.obj" />
  <mesh file="WHEEL_collision_9.obj" />
  <mesh file="WHEEL_collision_10.obj" />
  <mesh file="WHEEL_collision_11.obj" />
  <mesh file="WHEEL_collision_12.obj" />
  <mesh file="WHEEL_collision_13.obj" />
  <mesh file="WHEEL_collision_14.obj" />
  <mesh file="WHEEL_collision_15.obj" />
  <mesh file="WHEEL_collision_16.obj" />
  <mesh file="WHEEL_collision_17.obj" />
  <mesh file="WHEEL_collision_18.obj" />
  <mesh file="WHEEL_collision_19.obj" />
  <mesh file="WHEEL_collision_20.obj" />
  <mesh file="WHEEL_collision_21.obj" />
  <mesh file="WHEEL_collision_22.obj" />
  <mesh file="WHEEL_collision_23.obj" />
  <mesh file="WHEEL_collision_24.obj" />
  <mesh file="WHEEL_collision_25.obj" />
  <mesh file="WHEEL_collision_26.obj" />
  <mesh file="WHEEL_collision_27.obj" />
  <mesh file="WHEEL_collision_28.obj" />
  <mesh file="WHEEL_collision_29.obj" />
  <mesh file="WHEEL_collision_30.obj" />
  <mesh file="WHEEL_collision_31.obj" />
  <mesh file="WHEEL_collision_32.obj" />
  <mesh file="WHEEL_collision_33.obj" />
  <mesh file="WHEEL_collision_34.obj" />
  <mesh file="WHEEL_collision_35.obj" />
  <mesh file="WHEEL_collision_36.obj" />
  <mesh file="WHEEL_collision_37.obj" />
<mesh file="EE_BODY.obj" />
<mesh file="EE_FINGER_0.obj" />
  <mesh file="EE_FINGER_1.obj" />
<mesh file="FT_SENSOR_L_0.obj" />
  <mesh file="FT_SENSOR_L_1.obj" />
  <mesh file="FT_SENSOR_L_2.obj" />
  <mesh file="FT_SENSOR_L_3.obj" />
  <mesh file="FT_SENSOR_L_4.obj" />
  <mesh file="FT_SENSOR_L_5.obj" />
  <mesh file="FT_SENSOR_L_6.obj" />
  <mesh file="FT_SENSOR_L_7.obj" />
  <mesh file="FT_SENSOR_L_8.obj" />
  <mesh file="FT_SENSOR_L_9.obj" />
  <mesh file="FT_SENSOR_L_10.obj" />
<mesh file="FT_SENSOR_R_0.obj" />
  <mesh file="FT_SENSOR_R_1.obj" />
  <mesh file="FT_SENSOR_R_2.obj" />
  <mesh file="FT_SENSOR_R_3.obj" />
  <mesh file="FT_SENSOR_R_4.obj" />
  <mesh file="FT_SENSOR_R_5.obj" />
  <mesh file="FT_SENSOR_R_6.obj" />
  <mesh file="FT_SENSOR_R_7.obj" />
  <mesh file="FT_SENSOR_R_8.obj" />
  <mesh file="FT_SENSOR_R_9.obj" />
  <mesh file="FT_SENSOR_R_10.obj" />
<mesh file="LINK_1.obj" />
<mesh file="LINK_2_0.obj" />
  <mesh file="LINK_2_1.obj" />
<mesh file="LINK_3_0.obj" />
  <mesh file="LINK_3_1.obj" />
<mesh file="LINK_4.obj" />
<mesh file="LINK_5.obj" />
<mesh file="LINK_6_0.obj" />
  <mesh file="LINK_6_1.obj" />
  <mesh file="LINK_6_2.obj" />
  <mesh file="LINK_6_3.obj" />
  <mesh file="LINK_6_4.obj" />
  <mesh file="LINK_6_5.obj" />
<mesh file="LINK_7.obj" />
<mesh file="LINK_8.obj" />
<mesh file="LINK_9_0.obj" />
  <mesh file="LINK_9_1.obj" />
<mesh file="LINK_10_0.obj" />
  <mesh file="LINK_10_1.obj" />
<mesh file="LINK_11.obj" />
<mesh file="LINK_12_0.obj" />
  <mesh file="LINK_12_1.obj" />
<mesh file="LINK_13.obj" />
<mesh file="LINK_14.obj" />
<mesh file="LINK_15.obj" />
<mesh file="LINK_16_0.obj" />
  <mesh file="LINK_16_1.obj" />
<mesh file="LINK_17_0.obj" />
  <mesh file="LINK_17_1.obj" />
<mesh file="LINK_18.obj" />
<mesh file="LINK_19_0.obj" />
  <mesh file="LINK_19_1.obj" />
<mesh file="LINK_20.obj" />
<mesh file="PAN_TILT_1_0.obj" />
  <mesh file="PAN_TILT_1_1.obj" />
  <mesh file="PAN_TILT_1_2.obj" />
  <mesh file="PAN_TILT_1_3.obj" />
<mesh file="PAN_TILT_2_0.obj" />
  <mesh file="PAN_TILT_2_1.obj" />
  <mesh file="PAN_TILT_2_2.obj" />
<mesh file="PAN_TILT_3_0.obj" />
  <mesh file="PAN_TILT_3_1.obj" />
</asset>

  <worldbody>
    
    <light directional="true" diffuse=".8 .8 .8" specular="0 0 0" pos="0 0 5" dir="0 0 -1" castshadow="false" />
    <body name="base">
      <inertial pos="-0.0615794 -0.00142271 0.135139" quat="0.00383057 0.733861 -0.00742942 0.679248" mass="60.0804" diaginertia="3.77525 2.99424 1.36264" />
      <joint name="world_j" type="free" limited="false" actuatorfrclimited="false" />
      <geom mesh="base_0" material="255,255,255" class="visual" />
      <geom mesh="base_1" material="90,90,90" class="visual" />
      <geom mesh="base_2" material="130,130,130" class="visual" />
      <geom mesh="base_3" material="254,254,255" class="visual" />
      <geom mesh="base_4" material="156,168,171" class="visual" />
      <geom mesh="base_5" material="191,191,191" class="visual" />
      <geom mesh="base_6" material="69,69,69" class="visual" />
      <geom mesh="base_7" material="70,70,70" class="visual" />
      <geom type="box" size="0.34 0.3 0.1" pos="-0.01 0 0.1" class="collision" />
      <geom type="box" size="0.09 0.08 0.09" pos="-0.24 0 0.295" class="collision" />
<body name="wheel_fr_link" pos="0.243 -0.245 0.076">
        <inertial pos="-0.00010511 0.0009458 0" quat="0.707046 0 0 0.707168" mass="2.5441" diaginertia="0.00616429 0.00470985 0.00470754" />
        <joint name="wheel_fr" pos="0 0 0" axis="0 1 0" limited="true" range="-3.1415 3.1415" />
        <geom material="191,191,191" mesh="MECANUM_WHEEL" class="visual" />
</body>
      <body name="wheel_fl_link" pos="0.243 0.245 0.076">
        <inertial pos="-0.00010433 -0.00094577 0" quat="0.707168 0 0 0.707046" mass="2.54418" diaginertia="0.00616468 0.00471013 0.00470782" />
        <joint name="wheel_fl" pos="0 0 0" axis="0 1 0" limited="true" range="-3.1415 3.1415" />
        <geom material="191,191,191" mesh="MECANUM_WHEEL_M" class="visual" />
</body>
      <body name="wheel_rr_link" pos="-0.247 -0.245 0.076">
        <inertial pos="-0.00010433 -0.00094577 0" quat="0.707168 0 0 0.707046" mass="2.54418" diaginertia="0.00616468 0.00471013 0.00470782" />
        <joint name="wheel_rr" pos="0 0 0" axis="0 1 0" limited="true" range="-3.1415 3.1415" />
        <geom material="191,191,191" mesh="MECANUM_WHEEL_M" class="visual" />
</body>
      <body name="wheel_rl_link" pos="-0.247 0.245 0.076">
        <inertial pos="-0.00010511 0.0009458 0" quat="0.707046 0 0 0.707168" mass="2.5441" diaginertia="0.00616429 0.00470985 0.00470754" />
        <joint name="wheel_rl" pos="0 0 0" axis="0 1 0" limited="true" range="-3.1415 3.1415" />
        <geom material="191,191,191" mesh="MECANUM_WHEEL" class="visual" />
</body>

      <body name="link_torso_0" pos="0 0 0.2965">
        <inertial pos="-0.0884841 0.00021367 4.6e-07" quat="0.443798 0.550483 -0.443815 0.55049" mass="2.24282" diaginertia="0.0189253 0.0143368 0.00985172" />
        <joint name="torso_0" pos="0 0 0" axis="1 0 0" limited="true" range="-0.349066 0.349066" />
        <geom material="254,254,255" mesh="LINK_1" class="visual" />
  <geom type="sphere" size="0.08" pos="-0.1 0.045 0" class="collision" />
  <geom type="sphere" size="0.08" pos="-0.1 -0.045 0" class="collision" />
<body name="link_torso_1">
          <inertial pos="0.00728955 -0.0172852 0.0691138" quat="0.997768 -0.0453891 0.0382115 -0.0306483" mass="9.72163" diaginertia="0.149421 0.139376 0.0275059" />
          <joint name="torso_1" pos="0 0 0" axis="0 1 0" limited="true" range="-1.0472 1.52173" />
          <geom mesh="LINK_2_0" material="0,0,0" class="visual" />
  <geom mesh="LINK_2_1" material="254,254,255" class="visual" />
  <geom type="sphere" size="0.11" class="collision" />
  <geom type="sphere" size="0.085" pos="0.015 0 0.08" class="collision" />
  <geom type="sphere" size="0.07" pos="0.025 0.03 0.15" class="collision" />
  <geom type="sphere" size="0.07" pos="0.025 -0.03 0.15" class="collision" />
  <geom type="sphere" size="0.07" pos="0.025 0.04 0.22" class="collision" />
  <geom type="sphere" size="0.07" pos="0.025 -0.04 0.22" class="collision" />
  <geom type="sphere" size="0.06" pos="0.03 0.05 0.28" class="collision" />
  <geom type="sphere" size="0.06" pos="0.03 0 0.28" class="collision" />
  <geom type="sphere" size="0.06" pos="0.03 -0.05 0.28" class="collision" />
  <geom type="sphere" size="0.08" pos="0 0.05 0.35" class="collision" />
  <geom type="sphere" size="0.08" pos="0 -0.05 0.35" class="collision" />
<body name="link_torso_2" pos="0 0 0.35">
            <inertial pos="0.00653835 -0.0176954 0.0563658" quat="0.99687 -0.052526 0.0433482 -0.0401474" mass="9.21692" diaginertia="0.12242 0.116748 0.0292915" />
            <joint name="torso_2" pos="0 0 0" axis="0 1 0" limited="true" range="-2.47837 1.5708" />
            <geom mesh="LINK_3_0" material="10,10,10" class="visual" />
  <geom mesh="LINK_3_1" material="254,254,255" class="visual" />
  <geom type="sphere" size="0.09" class="collision" />
  <geom type="sphere" size="0.085" pos="0.015 0 0.08" class="collision" />
  <geom type="sphere" size="0.07" pos="0.025 0.03 0.15" class="collision" />
  <geom type="sphere" size="0.07" pos="0.025 -0.03 0.15" class="collision" />
  <geom type="sphere" size="0.07" pos="0.025 0.04 0.22" class="collision" />
  <geom type="sphere" size="0.07" pos="0.025 -0.04 0.22" class="collision" />
  <geom type="sphere" size="0.06" pos="0.03 0.05 0.28" class="collision" />
  <geom type="sphere" size="0.06" pos="0.03 0 0.28" class="collision" />
  <geom type="sphere" size="0.06" pos="0.03 -0.05 0.28" class="collision" />
  <geom type="sphere" size="0.06" pos="0.005 0.05 0.35" class="collision" />
  <geom type="sphere" size="0.06" pos="0.005 -0.05 0.35" class="collision" />
<body name="link_torso_3" pos="0 0 0.35">
              <inertial pos="-0.00574156 -0.0172598 5.61e-05" quat="0.0913806 0.682262 -0.18841 0.700478" mass="4.18679" diaginertia="0.00955618 0.00946572 0.00832635" />
              <joint name="torso_3" pos="0 0 0" axis="0 1 0" limited="true" range="-0.785398 1.5708" />
              <geom material="10,10,10" mesh="LINK_4" class="visual" />
<body name="link_torso_4">
                <inertial pos="-0.0909709 5.085e-05 0.0260195" quat="-0.0536434 0.4399 -0.0270045 0.896036" mass="4.45566" diaginertia="0.0255574 0.0255082 0.00942882" />
                <joint name="torso_4" pos="0 0 0" axis="1 0 0" limited="true" range="-0.523599 0.523599" />
                <geom material="10,10,10" mesh="LINK_5" class="visual" />
  <geom type="sphere" size="0.105" pos="0 0 0.03" class="collision" />
  <geom type="sphere" size="0.1" pos="-0.05 0 0.03" class="collision" />
  <geom type="sphere" size="0.1" pos="-0.1 0 0.03" class="collision" />
  <geom type="sphere" size="0.07" pos="-0.17 0 0" class="collision" />
<body name="link_torso_5" pos="0 0 0.309427">
                  <inertial pos="-0.0132199 0.000254676 -0.0318761" quat="0.998675 -0.00438307 -0.0510462 0.00477378" mass="12.6659" diaginertia="0.21618 0.167212 0.132309" />
                  <joint name="torso_5" pos="0 0 0" axis="0 0 1" limited="true" range="-1.5708 1.5708" />
                  <geom mesh="LINK_6_0" material="254,254,255_LINK_6" class="visual" />
  <geom mesh="LINK_6_1" material="191,191,191" class="visual" />
  <geom mesh="LINK_6_2" material="70,70,70" class="visual" />
  <geom mesh="LINK_6_3" material="178,0,0" class="visual" />
  <geom mesh="LINK_6_4" material="10,10,10_LINK_6" class="visual" />
  <geom mesh="LINK_6_5" material="254,254,255_LINK_6" class="visual" />
  <geom type="sphere" size="0.16" pos="0 0 0.025" class="collision" />
  <geom type="sphere" size="0.13" pos="-0.01 0 -0.1" class="collision" />
  <geom type="sphere" size="0.13" pos="-0.12 0 0.06" class="collision" />
  <geom type="sphere" size="0.13" pos="-0.1 0 -0.01" class="collision" />
  <geom type="sphere" size="0.12" pos="-0.09 0 -0.08" class="collision" />
<geom mesh="PAN_TILT_1_0" material="244,244,244" class="visual" />
  <geom mesh="PAN_TILT_1_1" material="69,69,69" class="visual" />
  <geom mesh="PAN_TILT_1_2" material="191,191,191" class="visual" />
  <geom mesh="PAN_TILT_1_3" material="254,254,255" class="visual" />
  <geom type="sphere" size="0.12" pos="0 0 0.04" class="collision" />
<body name="link_right_arm_0" pos="0 -0.22 0.0800735" quat="0.984808 -0.173648 0 0">
                    <inertial pos="-0.00316662 0.0343718 -3e-07" quat="0.536676 0.553304 0.439546 0.461122" mass="1.26164" diaginertia="0.00433912 0.00432154 0.00223129" />
                    <joint name="right_arm_0" pos="0 0 0" axis="0 1 0" limited="true" range="-2.35619 2.35619" />
                    <geom material="10,10,10" mesh="LINK_7" class="visual" />
  <geom type="sphere" size="0.075" pos="0.025 0.018 -0.005" class="collision" />
  <geom type="sphere" size="0.075" pos="-0.015 0.018 -0.005" class="collision" />
  <geom type="sphere" size="0.075" pos="-0.05 0.018 -0.005" class="collision" />
<body name="link_right_arm_1" quat="0.984808 0.173648 0 0">
                      <inertial pos="-0.00307855 -0.00124741 -0.0129432" quat="0.691024 -0.061096 -0.016345 0.72006" mass="2.27287" diaginertia="0.00447747 0.0038967 0.00286448" />
                      <joint name="right_arm_1" pos="0 0 0" axis="1 0 0" limited="true" range="-3.14159 0.05" />
                      <geom material="10,10,10" mesh="LINK_8" class="visual" />
  <geom type="sphere" size="0.05" pos="0 0 -0.07" class="collision" />
<body name="link_right_arm_2">
                        <inertial pos="0.00115434 -0.00196635 -0.161925" quat="0.998316 -0.0390505 -0.0388849 0.0181103" mass="2.46909" diaginertia="0.0098447 0.00928024 0.00322202" />
                        <joint name="right_arm_2" pos="0 0 0" axis="0 0 1" limited="true" range="-2.0944 2.0944" />
                        <geom mesh="LINK_9_0" material="254,254,255" class="visual" />
  <geom mesh="LINK_9_1" material="10,10,10" class="visual" />
  <geom type="sphere" size="0.05" pos="0 0 -0.11" class="collision" />
  <geom type="sphere" size="0.05" pos="0 0 -0.15" class="collision" />
  <geom type="sphere" size="0.05" pos="0 0 -0.19" class="collision" />
  <geom type="sphere" size="0.05" pos="0 0 -0.23" class="collision" />
  <geom type="sphere" size="0.05" pos="0 0.022 -0.24" class="collision" />
  <geom type="sphere" size="0.05" pos="0 -0.02 -0.24" class="collision" />
  <geom type="sphere" size="0.045" pos="0.031 0.042 -0.275" class="collision" />
  <geom type="sphere" size="0.045" pos="0.031 -0.04 -0.275" class="collision" />
<body name="link_right_arm_3" pos="0.031 0 -0.276">
                          <inertial pos="-0.0160313 -0.00692891 -0.0454981" quat="0.950945 0.0932571 0.100342 0.277377" mass="2.26099" diaginertia="0.0086724 0.00849326 0.00187523" />
                          <joint name="right_arm_3" pos="0 0 0" axis="0 1 0" limited="true" range="-2.61799 0.01" />
                          <geom mesh="LINK_10_0" material="254,254,255" class="visual" />
  <geom mesh="LINK_10_1" material="10,10,10" class="visual" />
  <geom type="sphere" size="0.06" pos="-0.015 0 0" class="collision" />
  <geom type="sphere" size="0.04" pos="-0.031 0 -0.06" class="collision" />
  <geom type="sphere" size="0.04" pos="-0.031 0 -0.09" class="collision" />
  <geom type="sphere" size="0.04" pos="-0.031 0 -0.132" class="collision" />
<body name="link_right_arm_4" pos="-0.031 0 -0.256">
                            <inertial pos="-1.1e-07 -0.0269604 0.0618211" quat="0.686909 -0.167796 0.167796 0.686909" mass="0.425087" diaginertia="0.000885625 0.00082466 0.000266295" />
                            <joint name="right_arm_4" pos="0 0 0" axis="0 0 1" limited="true" range="-6.28319 6.28319" />
                            <geom material="254,254,255" mesh="LINK_11" class="visual" />
  <geom type="sphere" size="0.04" pos="0 0 0.08" class="collision" />
  <geom type="sphere" size="0.04" pos="0 -0.027 0.07" class="collision" />
  <geom type="sphere" size="0.04" pos="0 -0.032 0.05" class="collision" />
  <geom type="sphere" size="0.04" pos="0 -0.032 0.025" class="collision" />
  <geom type="sphere" size="0.04" pos="0 -0.032 0" class="collision" />
<body name="link_right_arm_5">
                              <inertial pos="0.00318034 -0.00532264 -0.0280966" quat="0.559407 0.0608226 -0.0803636 0.822743" mass="1.59194" diaginertia="0.00262685 0.00255036 0.00151658" />
                              <joint name="right_arm_5" pos="0 0 0" axis="0 1 0" limited="true" range="-1.74533 2.00713" />
                              <geom mesh="LINK_12_0" material="10,10,10" class="visual" />
  <geom mesh="LINK_12_1" material="254,254,255" class="visual" />
  <geom type="sphere" size="0.065" pos="0.02 0 -0.021" class="collision" />
  <geom type="sphere" size="0.04" pos="0 0.04 0" class="collision" />
  <geom type="sphere" size="0.05" pos="0 0 -0.057" class="collision" />
<body name="link_right_arm_6">
                                <inertial pos="0.00101419 0.000398553 -0.149904" quat="0.730015 -0.0098152 -0.00428736 0.683347" mass="1.16921" diaginertia="0.00296506 0.00265919 0.00114611" />
                                <joint name="right_arm_6" pos="0 0 0" axis="0 0 1" limited="true" range="-2.96706 2.96706" />
                                <geom material="69,69,69" mesh="LINK_13" class="visual" />
  <geom type="sphere" size="0.05" pos="0 0 -0.1" class="collision" />
<body name="FT_SENSOR_R" pos="0 0 -0.1087">
                                  <inertial pos="0 0 0" mass="0" />
                                  <geom mesh="FT_SENSOR_R_0" material="254,254,255" class="visual" />
  <geom mesh="FT_SENSOR_R_1" material="65,55,50" class="visual" />
  <geom mesh="FT_SENSOR_R_2" material="80,80,80" class="visual" />
  <geom mesh="FT_SENSOR_R_3" material="244,244,244" class="visual" />
  <geom mesh="FT_SENSOR_R_4" material="191,191,191" class="visual" />
  <geom mesh="FT_SENSOR_R_5" material="216,214,214" class="visual" />
  <geom mesh="FT_SENSOR_R_6" material="79,79,79" class="visual" />
  <geom mesh="FT_SENSOR_R_7" material="192,192,192" class="visual" />
  <geom mesh="FT_SENSOR_R_8" material="163,163,175" class="visual" />
  <geom mesh="FT_SENSOR_R_9" material="242,236,238" class="visual" />
  <geom mesh="FT_SENSOR_R_10" material="69,69,69" class="visual" />
  <geom type="sphere" size="0.04" pos="0 0 -0.0275" class="collision" />
</body>
                                <body name="EE_BODY_R" pos="0 0 -0.1548">
                                  <site name="end_effector_r" size="0.01" />
                                  <inertial pos="0 0 0" mass="0" />
                                  <geom material="70,70,70" mesh="EE_BODY" class="visual" />
  <geom type="sphere" size="0.04" pos="0.025 0 -0.04" class="collision" />
  <geom type="sphere" size="0.04" pos="0 0 -0.04" class="collision" />
  <geom type="sphere" size="0.04" pos="-0.025 0 -0.04" class="collision" />
  <geom type="sphere" size="0.02" pos="0.05 -0.003 -0.06" class="collision" />
  <geom type="sphere" size="0.02" pos="-0.05 0.003 -0.06" class="collision" />
</body>
                              </body>
                            </body>
                          </body>
                        </body>
                      </body>
                    </body>
                  </body>
                  <body name="link_left_arm_0" pos="0 0.22 0.0800735" quat="0.984808 0.173648 0 0">
                    <inertial pos="-0.00316662 -0.0343715 2.42e-06" quat="0.441442 0.459281 0.538276 0.551768" mass="1.26164" diaginertia="0.0043391 0.00432158 0.00223133" />
                    <joint name="left_arm_0" pos="0 0 0" axis="0 1 0" limited="true" range="-2.35619 2.35619" />
                    <geom material="10,10,10" mesh="LINK_14" class="visual" />
  <geom type="sphere" pos="0.025 -0.018 -0.005" size="0.075" class="collision" />
  <geom type="sphere" pos="-0.015 -0.018 -0.005" size="0.075" class="collision" />
  <geom type="sphere" pos="-0.05 -0.018 -0.005" size="0.075" class="collision" />
<body name="link_left_arm_1" quat="0.984808 -0.173648 0 0">
                      <inertial pos="-0.0018347 0.00040596 -0.0100873" quat="0.701113 -0.0246572 -0.049881 0.710875" mass="1.88139" diaginertia="0.00355382 0.00296561 0.0022966" />
                      <joint name="left_arm_1" pos="0 0 0" axis="1 0 0" limited="true" range="-0.05 3.14159" />
                      <geom material="10,10,10" mesh="LINK_15" class="visual" />
  <geom type="sphere" size="0.05" pos="0 0 -0.07" class="collision" />
<body name="link_left_arm_2">
                        <inertial pos="0.00066086 -0.00038583 -0.15743" quat="0.999413 -0.00635373 -0.0335732 -0.00246859" mass="2.35634" diaginertia="0.00845197 0.00802394 0.00293109" />
                        <joint name="left_arm_2" pos="0 0 0" axis="0 0 1" limited="true" range="-2.0944 2.0944" />
                        <geom mesh="LINK_16_0" material="254,254,255" class="visual" />
  <geom mesh="LINK_16_1" material="10,10,10" class="visual" />
  <geom type="sphere" size="0.05" pos="0 0 -0.11" class="collision" />
  <geom type="sphere" size="0.05" pos="0 0 -0.15" class="collision" />
  <geom type="sphere" size="0.05" pos="0 0 -0.19" class="collision" />
  <geom type="sphere" size="0.05" pos="0 0 -0.23" class="collision" />
  <geom type="sphere" size="0.05" pos="0 0.02 -0.24" class="collision" />
  <geom type="sphere" size="0.05" pos="0 -0.022 -0.24" class="collision" />
  <geom type="sphere" size="0.045" pos="0.031 0.04 -0.275" class="collision" />
  <geom type="sphere" size="0.045" pos="0.031 -0.042 -0.275" class="collision" />
<body name="link_left_arm_3" pos="0.031 0 -0.276">
                          <inertial pos="-0.015653 0.00793126 -0.0499794" quat="0.977098 -0.0897025 0.113811 -0.15582" mass="2.00906" diaginertia="0.00798526 0.00783637 0.00146823" />
                          <joint name="left_arm_3" pos="0 0 0" axis="0 1 0" limited="true" range="-2.61799 0.01" />
                          <geom mesh="LINK_17_0" material="254,254,255" class="visual" />
  <geom mesh="LINK_17_1" material="10,10,10" class="visual" />
  <geom type="sphere" size="0.06" pos="-0.015 0 0" class="collision" />
  <geom type="sphere" size="0.04" pos="-0.031 0 -0.06" class="collision" />
  <geom type="sphere" size="0.04" pos="-0.031 0 -0.09" class="collision" />
  <geom type="sphere" size="0.04" pos="-0.031 0 -0.132" class="collision" />
<body name="link_left_arm_4" pos="-0.031 0 -0.256">
                            <inertial pos="1.1e-07 0.0269604 0.0618211" quat="0.686909 0.167796 -0.167796 0.686909" mass="0.425087" diaginertia="0.000885625 0.00082466 0.000266295" />
                            <joint name="left_arm_4" pos="0 0 0" axis="0 0 1" limited="true" range="-6.28319 6.28319" />
                            <geom material="254,254,255" mesh="LINK_18" class="visual" />
  <geom type="sphere" size="0.04" pos="0 0 0.08" class="collision" />
  <geom type="sphere" size="0.04" pos="0 0.027 0.07" class="collision" />
  <geom type="sphere" size="0.04" pos="0 0.032 0.05" class="collision" />
  <geom type="sphere" size="0.04" pos="0 0.032 0.025" class="collision" />
  <geom type="sphere" size="0.04" pos="0 0.032 0" class="collision" />
<body name="link_left_arm_5">
                              <inertial pos="0.00340082 0.00576824 -0.0250731" quat="0.874666 -0.0845974 0.0492323 0.474742" mass="1.44265" diaginertia="0.00238544 0.00231489 0.00134498" />
                              <joint name="left_arm_5" pos="0 0 0" axis="0 1 0" limited="true" range="-1.74533 2.00713" />
                              <geom mesh="LINK_19_0" material="10,10,10" class="visual" />
  <geom mesh="LINK_19_1" material="254,254,255" class="visual" />
  <geom type="sphere" size="0.065" pos="0.02 0 -0.021" class="collision" />
  <geom type="sphere" size="0.04" pos="0 -0.04 0" class="collision" />
  <geom type="sphere" size="0.05" pos="0 0 -0.057" class="collision" />
<body name="link_left_arm_6">
                                <inertial pos="-0.00092669 0.000508285 -0.149904" quat="0.72966 0.00249295 0.012223 0.683697" mass="1.16921" diaginertia="0.00296541 0.00265922 0.00114589" />
                                <joint name="left_arm_6" pos="0 0 0" axis="0 0 1" limited="true" range="-2.96706 2.96706" />
                                <geom material="69,69,69" mesh="LINK_20" class="visual" />
  <geom type="sphere" size="0.05" pos="0 0 -0.1" class="collision" />
<body name="FT_SENSOR_L" pos="0 0 -0.1087">
                                  <inertial pos="0 0 0" mass="0" />
                                  <geom mesh="FT_SENSOR_L_0" material="254,254,255" class="visual" />
  <geom mesh="FT_SENSOR_L_1" material="65,55,50" class="visual" />
  <geom mesh="FT_SENSOR_L_2" material="80,80,80" class="visual" />
  <geom mesh="FT_SENSOR_L_3" material="244,244,244" class="visual" />
  <geom mesh="FT_SENSOR_L_4" material="191,191,191" class="visual" />
  <geom mesh="FT_SENSOR_L_5" material="216,214,214" class="visual" />
  <geom mesh="FT_SENSOR_L_6" material="79,79,79" class="visual" />
  <geom mesh="FT_SENSOR_L_7" material="192,192,192" class="visual" />
  <geom mesh="FT_SENSOR_L_8" material="163,163,175" class="visual" />
  <geom mesh="FT_SENSOR_L_9" material="242,236,238" class="visual" />
  <geom mesh="FT_SENSOR_L_10" material="69,69,69" class="visual" />
  <geom type="sphere" size="0.04" pos="0 0 -0.0275" class="collision" />
  
</body>
                                <body name="EE_BODY_L" pos="0 0 -0.1548">
                                  <site name="end_effector_l" size="0.01" />
                                  <inertial pos="0 0 0" mass="0" />
                                  <geom material="70,70,70" mesh="EE_BODY" class="visual" />
  <geom type="sphere" size="0.04" pos="0.025 0 -0.04" class="collision" />
  <geom type="sphere" size="0.04" pos="0 0 -0.04" class="collision" />
  <geom type="sphere" size="0.04" pos="-0.025 0 -0.04" class="collision" />
  <geom type="sphere" size="0.02" pos="0.05 -0.003 -0.06" class="collision" />
  <geom type="sphere" size="0.02" pos="-0.05 0.003 -0.06" class="collision" />
</body>
                              </body>
                            </body>
                          </body>
                        </body>
                      </body>
                    </body>
                  </body>
                  <body name="link_head_1" pos="0.022 0 0.140073">
                    <inertial pos="-0.0115068 -0.0011427 -0.00031579" quat="0.354317 0.578329 0.650884 0.341093" mass="0.0745058" diaginertia="2.45449e-05 2.18237e-05 1.72614e-05" />
                    <joint name="head_0" pos="0 0 0" axis="0 0 1" limited="true" range="-0.523 0.523" />
                    <geom mesh="PAN_TILT_2_0" material="69,69,69_1" class="visual" />
  <geom mesh="PAN_TILT_2_1" material="191,191,191" class="visual" />
  <geom mesh="PAN_TILT_2_2" material="69,69,69" class="visual" />
<body name="link_head_2">
                      <site name="head" size="0.01" />
                      <inertial pos="-0.00081966 0.00099024 0.022837" quat="0.797736 0.60274 0.0137914 -0.0114992" mass="0.0358537" diaginertia="2.04697e-05 1.31161e-05 1.02242e-05" />
                      <joint name="head_1" pos="0 0 0" axis="0 1 0" limited="true" range="-0.35 1.57" />
                      <geom mesh="PAN_TILT_3_0" material="65,65,65" class="visual" />
  <geom mesh="PAN_TILT_3_1" material="69,69,69" class="visual" />
</body>
                  </body>
                </body>
              </body>
            </body>
          </body>
        </body>
      </body>
    </body>
  </worldbody>
</mujoco>